Workbook
Name _Bins1: ROUND((MOD(ROW(OFFSET(#REF!,0,0,_NumClasses1-1,1)),1)+#REF!)+(ROW(OFFSET(#REF!,0,0,_NumClasses1-1,1))-1)*_Spacing1,0)
Name _Bins1: ROUND((MOD(ROW(OFFSET(#REF!,0,0,_NumClasses1-1,1)),1)+#REF!)+(ROW(OFFSET(#REF!,0,0,_NumClasses1-1,1))-1)*_Spacing1,0)
Name _Bins1: ROUND((MOD(ROW(OFFSET(#REF!,0,0,_NumClasses1-1,1)),1)+#REF!)+(ROW(OFFSET(#REF!,0,0,_NumClasses1-1,1))-1)*_Spacing1,0)
Name _Bins1_Displaced: ROUND((MOD(ROW(OFFSET(#REF!,0,0,_NumClasses1-1,1)),1)+#REF!)+(ROW(OFFSET(#REF!,0,0,_NumClasses1-1,1))-2)*_Spacing1,0)
Name _Bins1_Displaced: ROUND((MOD(ROW(OFFSET(#REF!,0,0,_NumClasses1-1,1)),1)+#REF!)+(ROW(OFFSET(#REF!,0,0,_NumClasses1-1,1))-2)*_Spacing1,0)
Name _Bins1_Displaced: ROUND((MOD(ROW(OFFSET(#REF!,0,0,_NumClasses1-1,1)),1)+#REF!)+(ROW(OFFSET(#REF!,0,0,_NumClasses1-1,1))-2)*_Spacing1,0)
Name _Conditions3: #REF!
Name _Frequency1: FREQUENCY(_HousePrices,HT!_Bins1)
Name _Frequency1: FREQUENCY(_HousePrices,SampleSize!_Bins1)
Name _Frequency1: FREQUENCY(_HousePrices,_Bins1)
Name _HorLabels1: IF(ROW(OFFSET(#REF!,0,0,_NumClasses1,1))=1,"Up to "&#REF!,IF(ROW(OFFSET(#REF!,0,0,_NumClasses1,1))=_NumClasses1,"Greater than "&#REF!,"Greater than " &HT!_Bins1_Displaced&" to "&HT!_Bins1))
Name _HorLabels1: IF(ROW(OFFSET(#REF!,0,0,_NumClasses1,1))=1,"Up to "&#REF!,IF(ROW(OFFSET(#REF!,0,0,_NumClasses1,1))=_NumClasses1,"Greater than "&#REF!,"Greater than " &_Bins1_Displaced&" to "&_Bins1))
Name _HousePrices: #REF!
Name _HousePrices1A: IF(#REF!=1,#REF!,"")
Name _HousePrices1B: IF(#REF!=2,#REF!,"")
Name _HousePrices1C: IF(#REF!=3,#REF!,"")
Name _HousePrices3_Excellent: IF(#REF!=4,#REF!,"")
Name _HousePrices3_Good: IF(#REF!=3,#REF!,"")
Name _HousePrices3_Poor: IF(#REF!=2,#REF!,"")
Name _HousePrices3_VeryPoor: IF(#REF!=1,#REF!,"")
Name _HousePrices4_Owner: IF(#REF!=3,#REF!,"")
Name _HousePrices4_Rented: IF(#REF!=2,#REF!,"")
Name _HousePrices4_Vacant: IF(#REF!=1,#REF!,"")
Name _Mean2BySuburb: #REF!
Name _Mean3ByCondition: #REF!
Name _Mean4ByRentalStatus: #REF!
Name _NumClasses1: MAX(1,#REF!)
Name _RelFrequency1: HT!_Frequency1/#REF!*100
Name _RelFrequency1: SampleSize!_Frequency1/#REF!*100
Name _RelFrequency1: _Frequency1/#REF!*100
Name _RelFrequency2A: FREQUENCY(_HousePrices1A,HT!_Bins1)/#REF!*100
Name _RelFrequency2A: FREQUENCY(_HousePrices1A,SampleSize!_Bins1)/#REF!*100
Name _RelFrequency2A: FREQUENCY(_HousePrices1A,_Bins1)/#REF!*100
Name _RelFrequency2B: FREQUENCY(_HousePrices1B,HT!_Bins1)/#REF!*100
Name _RelFrequency2B: FREQUENCY(_HousePrices1B,SampleSize!_Bins1)/#REF!*100
Name _RelFrequency2B: FREQUENCY(_HousePrices1B,_Bins1)/#REF!*100
Name _RelFrequency2C: FREQUENCY(_HousePrices1C,HT!_Bins1)/#REF!*100
Name _RelFrequency2C: FREQUENCY(_HousePrices1C,SampleSize!_Bins1)/#REF!*100
Name _RelFrequency2C: FREQUENCY(_HousePrices1C,_Bins1)/#REF!*100
Name _RelFrequency3b_Excellent: FREQUENCY(_HousePrices3_Excellent,HT!_Bins1)/#REF!*100
Name _RelFrequency3b_Excellent: FREQUENCY(_HousePrices3_Excellent,SampleSize!_Bins1)/#REF!*100
Name _RelFrequency3b_Excellent: FREQUENCY(_HousePrices3_Excellent,_Bins1)/#REF!*100
Name _RelFrequency3b_Good: FREQUENCY(_HousePrices3_Good,HT!_Bins1)/#REF!*100
Name _RelFrequency3b_Good: FREQUENCY(_HousePrices3_Good,SampleSize!_Bins1)/#REF!*100
Name _RelFrequency3b_Good: FREQUENCY(_HousePrices3_Good,_Bins1)/#REF!*100
Name _RelFrequency3b_Poor: FREQUENCY(_HousePrices3_Poor,HT!_Bins1)/#REF!*100
Name _RelFrequency3b_Poor: FREQUENCY(_HousePrices3_Poor,SampleSize!_Bins1)/#REF!*100
Name _RelFrequency3b_Poor: FREQUENCY(_HousePrices3_Poor,_Bins1)/#REF!*100
Name _RelFrequency3b_VeryPoor: FREQUENCY(_HousePrices3_VeryPoor,HT!_Bins1)/#REF!*100
Name _RelFrequency3b_VeryPoor: FREQUENCY(_HousePrices3_VeryPoor,SampleSize!_Bins1)/#REF!*100
Name _RelFrequency3b_VeryPoor: FREQUENCY(_HousePrices3_VeryPoor,_Bins1)/#REF!*100
Name _RelFrequency4_Owner: FREQUENCY(_HousePrices4_Owner,HT!_Bins1)/#REF!*100
Name _RelFrequency4_Owner: FREQUENCY(_HousePrices4_Owner,SampleSize!_Bins1)/#REF!*100
Name _RelFrequency4_Owner: FREQUENCY(_HousePrices4_Owner,_Bins1)/#REF!*100
Name _RelFrequency4_Rented: FREQUENCY(_HousePrices4_Rented,HT!_Bins1)/#REF!*100
Name _RelFrequency4_Rented: FREQUENCY(_HousePrices4_Rented,SampleSize!_Bins1)/#REF!*100
Name _RelFrequency4_Rented: FREQUENCY(_HousePrices4_Rented,_Bins1)/#REF!*100
Name _RelFrequency4_Vacant: FREQUENCY(_HousePrices4_Vacant,HT!_Bins1)/#REF!*100
Name _RelFrequency4_Vacant: FREQUENCY(_HousePrices4_Vacant,SampleSize!_Bins1)/#REF!*100
Name _RelFrequency4_Vacant: FREQUENCY(_HousePrices4_Vacant,_Bins1)/#REF!*100

Sheet Variable Descriptions
A1: Variable Name | B1: Description
A2: Cust_ID | B2: Unique customer identifier assigned to each individual.
A3: Age | B3: Age of the customer in years, ranging from 18 to 75.
A4: Gender | B4: Gender category: Male, Female, or Other, based on self-identification.
A5: State | B5: Australian state where the customer resides (e.g., NSW, VIC, QLD, etc.).
A6: Marital | B6: Marital status of the customer: Single, Married, Divorced, or Widowed.
A7: Edu_Level | B7: Highest level of education completed: High School, Bachelor's, Master's, or PhD.
A8: Income | B8: Annual income of the customer in thousands of AUD (e.g., 50 represents $50,000 AUD).
A9: Total_Spend | B9: Total amount spent by the customer at AussieMart in the last year, measured in thousands of AUD (e.g., 10 represents $10,000 AUD).
A10: Num_Trans | B10: Total number of purchases made by the customer at AussieMart within the last year.
A11: Avg_Trans | B11: Average amount spent per transaction, calculated as Total Spending divided by Number of Transactions.
A12: Loyalty | B12: Indicates whether the customer is enrolled in the AussieMart loyalty program (Yes/No).
... A17: Return_Rate | B17: The percentage of purchases that the customer returned, ranging from 0% to 50%.

Sheet Customer Data Set
A1: Cust_ID | B1: Age | C1: Gender | D1: State | E1: Marital | F1: Edu_Level | G1: Income | H1: Total_Spend | I1: Num_Trans | J1: Avg_Trans | K1: Loyalty | L1: Online_Freq | M1: Pref_Cat | N1: Disc_Usage | O1: Sat_Score | P1: Return_Rate
A2: CUST0001 | B2: 67 | C2: Female | D2: NSW | E2: Married | F2: Master's | G2: 33.696 | H2: 17.388 | I2: 19 | J2: 146.12 | K2: Yes | L2: Rarely | M2: Sports | N2: Frequently | O2: 2 | P2: 0.57
A3: CUST0002 | B3: 20 | C3: Female | D3: QLD | E3: Single | F3: Bachelor's | G3: 230.4 | H3: 46.657 | I3: 11 | J3: 690.6 | K3: Yes | L3: Rarely | M3: Sports | N3: Occasionally | O3: 8 | P3: 0.84
A4: CUST0003 | B4: 43 | C4: Female | D4: ACT | E4: Single | F4: Bachelor's | G4: 91.149 | H4: 68.616 | I4: 74 | J4: 927.24 | K4: Yes | L4: Sometimes | M4: Sports | N4: Occasionally | O4: 10 | P4: 12.19
A5: CUST0004 | B5: 51 | C5: Male | D5: SA | E5: Married | F5: Master's | G5: 52.318 | H5: 28.392 | I5: 97 | J5: 808.16 | K5: Yes | L5: Often | M5: Beauty | N5: Occasionally | O5: 10 | P5: 31.92
A6: CUST0005 | B6: 57 | C6: Other | D6: WA | E6: Single | F6: PhD | G6: 35.487 | H6: 43.87 | I6: 10 | J6: 6387 | K6: No | L6: Sometimes | M6: Home & Kitchen | N6: Occasionally | O6: 1 | P6: 44.82
A7: CUST0006 | B7: 40 | C7: Female | D7: VIC | E7: Single | F7: High School | G7: 187.886 | H7: 65.685 | I7: 104 | J7: 631.59 | K7: Yes | L7: Often | M7: Beauty | N7: Occasionally | O7: 10 | P7: 13.65
A8: CUST0007 | B8: 74 | C8: Female | D8: NSW | E8: Married | F8: Bachelor's | G8: 62.288 | H8: 25.865 | I8: 97 | J8: 266.65 | K8: No | L8: Rarely | M8: Sports | N8: Occasionally | O8: 3 | P8: 29.2
A9: CUST0008 | B9: 41 | C9: Male | D9: NT | E9: Married | F9: Bachelor's | G9: 42.994 | H9: 40.754 | I9: 38 | J9: 1072.47 | K9: No | L9: Often | M9: Clothing | N9: Occasionally | O9: 5 | P9: 37.35
A10: CUST0009 | B10: 69 | C10: Male | D10: NT | E10: Married | F10: High School | G10: 213.853 | H10: 16.122 | I10: 58 | J10: 277.97 | K10: No | L10: Often | M10: Home & Kitchen | N10: Occasionally | O10: 1 | P10: 49.22
A11: CUST0010 | B11: 53 | C11: Male | D11: NT | E11: Single | F11: Bachelor's | G11: 114.109 | H11: 43.776 | I11: 88 | J11: 497.45 | K11: Yes | L11: Sometimes | M11: Electronics | N11: Occasionally | O11: 9 | P11: 4.31
A12: CUST0011 | B12: 51 | C12: Male | D12: SA | E12: Divorced | F12: Master's | G12: 46.691 | H12: 63.608 | I12: 36 | J12: 1766.89 | K12: No | L12: Rarely | M12: Electronics | N12: Occasionally | O12: 2 | P12: 14.84
A13: CUST0012 | B13: 42 | C13: Male | D13: TAS | E13: Married | F13: Bachelor's | G13: 248.828 | H13: 35.884 | I13: 45 | J13: 1686.31 | K13: Yes | L13: Often | M13: Electronics | N13: Frequently | O13: 8 | P13: 20.05
... A401: CUST0400 | B401: 51 | C401: Male | D401: TAS | E401: Single | F401: Master's | G401: 91.25 | H401: 22.757 | I401: 84 | J401: 270.92 | K401: Yes | L401: Sometimes | M401: Home & Kitchen | N401: Occasionally | O401: 7 | P401: 25.82

Sheet Q1(a)
A1: Total_Spend | C1: Customer Spending Overview through Total_Spend
A2: 17.388
A3: 46.657
A4: 68.616 | E4: Descriptive Summary Table — Total_Spend
A5: 28.392 | E5: Total_Spend Summary
A6: 43.87 | E6: Statistics | F6: Value
A7: 65.685 | E7: Mean | F7: =AVERAGE(A2:A401) -> 49.252745
A8: 25.865 | E8: Standard Error | F8: =F11/SQRT(F19) -> 1.1803808
A9: 40.754 | E9: Median | F9: =MEDIAN(A2:A401) -> 47.622
A10: 16.122 | E10: Mode | F10: =MODE(A2:A401) -> 21.079
A11: 43.776 | E11: Standard Deviation | F11: =_xlfn.STDEV.S(A2:A401) -> 23.607615
A12: 63.608 | E12: Sample Variance | F12: =_xlfn.VAR.S(A2:A401) -> 557.31949
A13: 35.884 | E13: Kurtosis | F13: =KURT(A2:A401) -> 0.18710352
A14: 59.943 | E14: Skewness | F14: =SKEW(A2:A401) -> 0.43613418
A15: 55.834 | E15: Range | F15: =F17-F16 -> 131.947
A16: 15.707 | E16: Minimum | F16: =MIN(A2:A401) -> 5.693
A17: 67.504 | E17: Maximum | F17: =MAX(A2:A401) -> 137.64
A18: 42.305 | E18: Sum | F18: =SUM(A2:A401) -> 19701.098
A19: 45.494 | E19: Count | F19: =COUNT(A2:A401) -> 400
A20: 25.003
A21: 46.646
A22: 32.248 | E22: Percentiles and Quartles for Outlier Detection
A23: 71.543 | E23: statistics | F23: value
A24: 37.269 | E24: Q1 | F24: =_xlfn.PERCENTILE.EXC(A2:A401,0.25) -> 30.615
A25: 34.419 | E25: Q3 | F25: =_xlfn.PERCENTILE.EXC(A2:A401,0.75) -> 66.55075
A26: 62.975 | E26: IQR | F26: =F25-F24 -> 35.93575
A27: 51.877
A28: 38.255
A29: 20.73
A30: 42.258
A31: 66.81
A32: 8.32 | D32: Box Plot of Customer Spending
A33: 76.06
A34: 69.683
A35: 12.763
A36: 71.554
A37: 25.687
A38: 79.508
A39: 55.864
A40: 21.869
...

Sheet Q1(b)
A1: Online_Freq | C1: Customers Shopping habits through Online_Freq
A2: Rarely
A3: Rarely
A4: Sometimes | F4: Online-purchase Frequency-Distribution
A5: Often | F5: Online Purchase Frequency | G5: Customer Count | H5: Percentage of Total
A6: Sometimes | F6: Always | G6: =COUNTIF('Customer Data Set'!L:L,'Q1(b)'!F6) -> 38 | H6: =G6/COUNTA('Customer Data Set'!L:L) -> 0.094763092
A7: Often | F7: Often | G7: =COUNTIF('Customer Data Set'!L:L,'Q1(b)'!F7) -> 110 | H7: =G7/COUNTA('Customer Data Set'!L:L) -> 0.27431421
A8: Rarely | F8: Rarely | G8: =COUNTIF('Customer Data Set'!L:L,'Q1(b)'!F8) -> 88 | H8: =G8/COUNTA('Customer Data Set'!L:L) -> 0.21945137
A9: Often | F9: Sometimes | G9: =COUNTIF('Customer Data Set'!L:L,'Q1(b)'!F9) -> 164 | H9: =G9/COUNTA('Customer Data Set'!L:L) -> 0.40897756
A10: Often
A11: Sometimes
A12: Rarely | F12: DESCRIPTIVE_STATISTICS
A13: Often | F13: Statistical Summary | G13: Value
A14: Rarely | F14: Mode | G14: Sometimes
A15: Sometimes | F15: Frequency (Count) | G15: 164 Customers
A16: Rarely | F16: % of Total | G16: 0.409
A17: Often | F17: Total Responses | G17: 400 Customers
A18: Sometimes | F18: Number of Categories | G18: 4
A19: Always
A20: Always
A21: Rarely
A22: Rarely
A23: Rarely
A24: Sometimes | E24: Pie Chart for Customer Online Shopping Frequency
A25: Often
A26: Rarely
A27: Often
A28: Sometimes
A29: Often
A30: Always
A31: Rarely
A32: Sometimes
A33: Sometimes
A34: Rarely
A35: Rarely
A36: Sometimes
... A58: Rarely
A59: Often | E59: Bar Chart for Number of Customers by Shopping Frequency
A60: Sometimes
A61: Often
...

Sheet Q2(a)
A1: Total_Spend | B1: Num_Trans | C1: Spending_Groups | E1: Analyzing Total Spend vs Num_Trans
A2: 17.388 | B2: 19 | C2: =IF(A2<22, "Low Spend (<$22,000)", IF(A2<=44, "Lower-Middle Spend ($23,000 - $44,000)", IF(A2<=66, "Middle Spend ($45,000 - $66,000)", IF(A2<=88, "Upper-Middle Spend ($67,000 - $88,000)", IF(A2<=132, "High Spend ($89,000 - $132,000)", "Premium Spend (>$132,000)"))))) -> Low Spend (<$22,000) | D2: The Spending Group Column sorts customers by how much they spend, making it easier to understand their buying habits and create better strategies for different customer type
A3: 46.657 | B3: 11 | C3: =IF(A3<22, "Low Spend (<$22,000)", IF(A3<=44, "Lower-Middle Spend ($23,000 - $44,000)", IF(A3<=66, "Middle Spend ($45,000 - $66,000)", IF(A3<=88, "Upper-Middle Spend ($67,000 - $88,000)", IF(A3<=132, "High Spend ($89,000 - $132,000)", "Premium Spend (>$132,000)"))))) -> Middle Spend ($45,000 - $66,000)
A4: 68.616 | B4: 74 | C4: =IF(A4<22, "Low Spend (<$22,000)", IF(A4<=44, "Lower-Middle Spend ($23,000 - $44,000)", IF(A4<=66, "Middle Spend ($45,000 - $66,000)", IF(A4<=88, "Upper-Middle Spend ($67,000 - $88,000)", IF(A4<=132, "High Spend ($89,000 - $132,000)", "Premium Spend (>$132,000)"))))) -> Upper-Middle Spend ($67,000 - $88,000)
A5: 28.392 | B5: 97 | C5: =IF(A5<22, "Low Spend (<$22,000)", IF(A5<=44, "Lower-Middle Spend ($23,000 - $44,000)", IF(A5<=66, "Middle Spend ($45,000 - $66,000)", IF(A5<=88, "Upper-Middle Spend ($67,000 - $88,000)", IF(A5<=132, "High Spend ($89,000 - $132,000)", "Premium Spend (>$132,000)"))))) -> Lower-Middle Spend ($23,000 - $44,000) | G5: Descriptive Statistics for Total Spend and Number of Transactions
A6: 43.87 | B6: 10 | C6: =IF(A6<22, "Low Spend (<$22,000)", IF(A6<=44, "Lower-Middle Spend ($23,000 - $44,000)", IF(A6<=66, "Middle Spend ($45,000 - $66,000)", IF(A6<=88, "Upper-Middle Spend ($67,000 - $88,000)", IF(A6<=132, "High Spend ($89,000 - $132,000)", "Premium Spend (>$132,000)"))))) -> Lower-Middle Spend ($23,000 - $44,000) | G6: Metric | H6: Total_Spend | I6: Num_Trans
A7: 65.685 | B7: 104 | C7: =IF(A7<22, "Low Spend (<$22,000)", IF(A7<=44, "Lower-Middle Spend ($23,000 - $44,000)", IF(A7<=66, "Middle Spend ($45,000 - $66,000)", IF(A7<=88, "Upper-Middle Spend ($67,000 - $88,000)", IF(A7<=132, "High Spend ($89,000 - $132,000)", "Premium Spend (>$132,000)"))))) -> Middle Spend ($45,000 - $66,000) | G7: Mean | H7: 49.252745 | I7: 51.8875
A8: 25.865 | B8: 97 | C8: =IF(A8<22, "Low Spend (<$22,000)", IF(A8<=44, "Lower-Middle Spend ($23,000 - $44,000)", IF(A8<=66, "Middle Spend ($45,000 - $66,000)", IF(A8<=88, "Upper-Middle Spend ($67,000 - $88,000)", IF(A8<=132, "High Spend ($89,000 - $132,000)", "Premium Spend (>$132,000)"))))) -> Lower-Middle Spend ($23,000 - $44,000) | G8: Standard Error | H8: 1.1803808 | I8: 1.4661509
A9: 40.754 | B9: 38 | C9: =IF(A9<22, "Low Spend (<$22,000)", IF(A9<=44, "Lower-Middle Spend ($23,000 - $44,000)", IF(A9<=66, "Middle Spend ($45,000 - $66,000)", IF(A9<=88, "Upper-Middle Spend ($67,000 - $88,000)", IF(A9<=132, "High Spend ($89,000 - $132,000)", "Premium Spend (>$132,000)"))))) -> Lower-Middle Spend ($23,000 - $44,000) | G9: Median | H9: 47.622 | I9: 48
A10: 16.122 | B10: 58 | C10: =IF(A10<22, "Low Spend (<$22,000)", IF(A10<=44, "Lower-Middle Spend ($23,000 - $44,000)", IF(A10<=66, "Middle Spend ($45,000 - $66,000)", IF(A10<=88, "Upper-Middle Spend ($67,000 - $88,000)", IF(A10<=132, "High Spend ($89,000 - $132,000)", "Premium Spend (>$132,000)"))))) -> Low Spend (<$22,000) | G10: Mode | H10: 21.079 | I10: 43
A11: 43.776 | B11: 88 | C11: =IF(A11<22, "Low Spend (<$22,000)", IF(A11<=44, "Lower-Middle Spend ($23,000 - $44,000)", IF(A11<=66, "Middle Spend ($45,000 - $66,000)", IF(A11<=88, "Upper-Middle Spend ($67,000 - $88,000)", IF(A11<=132, "High Spend ($89,000 - $132,000)", "Premium Spend (>$132,000)"))))) -> Lower-Middle Spend ($23,000 - $44,000) | G11: Standard Deviation | H11: 23.607615 | I11: 29.323019
A12: 63.608 | B12: 36 | C12: =IF(A12<22, "Low Spend (<$22,000)", IF(A12<=44, "Lower-Middle Spend ($23,000 - $44,000)", IF(A12<=66, "Middle Spend ($45,000 - $66,000)", IF(A12<=88, "Upper-Middle Spend ($67,000 - $88,000)", IF(A12<=132, "High Spend ($89,000 - $132,000)", "Premium Spend (>$132,000)"))))) -> Middle Spend ($45,000 - $66,000) | G12: Sample Variance | H12: 557.31949 | I12: 859.83944
A13: 35.884 | B13: 45 | C13: =IF(A13<22, "Low Spend (<$22,000)", IF(A13<=44, "Lower-Middle Spend ($23,000 - $44,000)", IF(A13<=66, "Middle Spend ($45,000 - $66,000)", IF(A13<=88, "Upper-Middle Spend ($67,000 - $88,000)", IF(A13<=132, "High Spend ($89,000 - $132,000)", "Premium Spend (>$132,000)"))))) -> Lower-Middle Spend ($23,000 - $44,000) | G13: Kurtosis | H13: 0.18710352 | I13: -0.35715387
A14: 59.943 | B14: 51 | C14: =IF(A14<22, "Low Spend (<$22,000)", IF(A14<=44, "Lower-Middle Spend ($23,000 - $44,000)", IF(A14<=66, "Middle Spend ($45,000 - $66,000)", IF(A14<=88, "Upper-Middle Spend ($67,000 - $88,000)", IF(A14<=132, "High Spend ($89,000 - $132,000)", "Premium Spend (>$132,000)"))))) -> Middle Spend ($45,000 - $66,000) | G14: Skewness | H14: 0.43613418 | I14: 0.47412262
A15: 55.834 | B15: 48 | C15: =IF(A15<22, "Low Spend (<$22,000)", IF(A15<=44, "Lower-Middle Spend ($23,000 - $44,000)", IF(A15<=66, "Middle Spend ($45,000 - $66,000)", IF(A15<=88, "Upper-Middle Spend ($67,000 - $88,000)", IF(A15<=132, "High Spend ($89,000 - $132,000)", "Premium Spend (>$132,000)"))))) -> Middle Spend ($45,000 - $66,000) | G15: Range | H15: 131.947 | I15: 145
A16: 15.707 | B16: 41 | C16: =IF(A16<22, "Low Spend (<$22,000)", IF(A16<=44, "Lower-Middle Spend ($23,000 - $44,000)", IF(A16<=66, "Middle Spend ($45,000 - $66,000)", IF(A16<=88, "Upper-Middle Spend ($67,000 - $88,000)", IF(A16<=132, "High Spend ($89,000 - $132,000)", "Premium Spend (>$132,000)"))))) -> Low Spend (<$22,000) | G16: Minimum | H16: 5.693 | I16: 5
A17: 67.504 | B17: 71 | C17: =IF(A17<22, "Low Spend (<$22,000)", IF(A17<=44, "Lower-Middle Spend ($23,000 - $44,000)", IF(A17<=66, "Middle Spend ($45,000 - $66,000)", IF(A17<=88, "Upper-Middle Spend ($67,000 - $88,000)", IF(A17<=132, "High Spend ($89,000 - $132,000)", "Premium Spend (>$132,000)"))))) -> Upper-Middle Spend ($67,000 - $88,000) | G17: Maximum | H17: 137.64 | I17: 150
A18: 42.305 | B18: 48 | C18: =IF(A18<22, "Low Spend (<$22,000)", IF(A18<=44, "Lower-Middle Spend ($23,000 - $44,000)", IF(A18<=66, "Middle Spend ($45,000 - $66,000)", IF(A18<=88, "Upper-Middle Spend ($67,000 - $88,000)", IF(A18<=132, "High Spend ($89,000 - $132,000)", "Premium Spend (>$132,000)"))))) -> Lower-Middle Spend ($23,000 - $44,000) | G18: Sum | H18: 19701.098 | I18: 20755
A19: 45.494 | B19: 18 | C19: =IF(A19<22, "Low Spend (<$22,000)", IF(A19<=44, "Lower-Middle Spend ($23,000 - $44,000)", IF(A19<=66, "Middle Spend ($45,000 - $66,000)", IF(A19<=88, "Upper-Middle Spend ($67,000 - $88,000)", IF(A19<=132, "High Spend ($89,000 - $132,000)", "Premium Spend (>$132,000)"))))) -> Middle Spend ($45,000 - $66,000) | G19: Count | H19: 400 | I19: 400
A20: 25.003 | B20: 31 | C20: =IF(A20<22, "Low Spend (<$22,000)", IF(A20<=44, "Lower-Middle Spend ($23,000 - $44,000)", IF(A20<=66, "Middle Spend ($45,000 - $66,000)", IF(A20<=88, "Upper-Middle Spend ($67,000 - $88,000)", IF(A20<=132, "High Spend ($89,000 - $132,000)", "Premium Spend (>$132,000)"))))) -> Lower-Middle Spend ($23,000 - $44,000)
A21: 46.646 | B21: 43 | C21: =IF(A21<22, "Low Spend (<$22,000)", IF(A21<=44, "Lower-Middle Spend ($23,000 - $44,000)", IF(A21<=66, "Middle Spend ($45,000 - $66,000)", IF(A21<=88, "Upper-Middle Spend ($67,000 - $88,000)", IF(A21<=132, "High Spend ($89,000 - $132,000)", "Premium Spend (>$132,000)"))))) -> Middle Spend ($45,000 - $66,000)
A22: 32.248 | B22: 50 | C22: =IF(A22<22, "Low Spend (<$22,000)", IF(A22<=44, "Lower-Middle Spend ($23,000 - $44,000)", IF(A22<=66, "Middle Spend ($45,000 - $66,000)", IF(A22<=88, "Upper-Middle Spend ($67,000 - $88,000)", IF(A22<=132, "High Spend ($89,000 - $132,000)", "Premium Spend (>$132,000)"))))) -> Lower-Middle Spend ($23,000 - $44,000)
A23: 71.543 | B23: 75 | C23: =IF(A23<22, "Low Spend (<$22,000)", IF(A23<=44, "Lower-Middle Spend ($23,000 - $44,000)", IF(A23<=66, "Middle Spend ($45,000 - $66,000)", IF(A23<=88, "Upper-Middle Spend ($67,000 - $88,000)", IF(A23<=132, "High Spend ($89,000 - $132,000)", "Premium Spend (>$132,000)"))))) -> Upper-Middle Spend ($67,000 - $88,000)
A24: 37.269 | B24: 31 | C24: =IF(A24<22, "Low Spend (<$22,000)", IF(A24<=44, "Lower-Middle Spend ($23,000 - $44,000)", IF(A24<=66, "Middle Spend ($45,000 - $66,000)", IF(A24<=88, "Upper-Middle Spend ($67,000 - $88,000)", IF(A24<=132, "High Spend ($89,000 - $132,000)", "Premium Spend (>$132,000)"))))) -> Lower-Middle Spend ($23,000 - $44,000) | F24: Commparitive Summary
A25: 34.419 | B25: 64 | C25: =IF(A25<22, "Low Spend (<$22,000)", IF(A25<=44, "Lower-Middle Spend ($23,000 - $44,000)", IF(A25<=66, "Middle Spend ($45,000 - $66,000)", IF(A25<=88, "Upper-Middle Spend ($67,000 - $88,000)", IF(A25<=132, "High Spend ($89,000 - $132,000)", "Premium Spend (>$132,000)"))))) -> Lower-Middle Spend ($23,000 - $44,000) | F25: Spending_Groups | G25: Sum of Num_Trans | H25: Average of Total_Spend | I25: Count of Customers
A26: 62.975 | B26: 40 | C26: =IF(A26<22, "Low Spend (<$22,000)", IF(A26<=44, "Lower-Middle Spend ($23,000 - $44,000)", IF(A26<=66, "Middle Spend ($45,000 - $66,000)", IF(A26<=88, "Upper-Middle Spend ($67,000 - $88,000)", IF(A26<=132, "High Spend ($89,000 - $132,000)", "Premium Spend (>$132,000)"))))) -> Middle Spend ($45,000 - $66,000) | F26: High Spend ($89,000 - $132,000) | G26: 1135 | H26: 97.7735 | I26: 16
A27: 51.877 | B27: 62 | C27: =IF(A27<22, "Low Spend (<$22,000)", IF(A27<=44, "Lower-Middle Spend ($23,000 - $44,000)", IF(A27<=66, "Middle Spend ($45,000 - $66,000)", IF(A27<=88, "Upper-Middle Spend ($67,000 - $88,000)", IF(A27<=132, "High Spend ($89,000 - $132,000)", "Premium Spend (>$132,000)"))))) -> Middle Spend ($45,000 - $66,000) | F27: Low Spend (<$22,000) | G27: 2180 | H27: 14.814269 | I27: 52
A28: 38.255 | B28: 13 | C28: =IF(A28<22, "Low Spend (<$22,000)", IF(A28<=44, "Lower-Middle Spend ($23,000 - $44,000)", IF(A28<=66, "Middle Spend ($45,000 - $66,000)", IF(A28<=88, "Upper-Middle Spend ($67,000 - $88,000)", IF(A28<=132, "High Spend ($89,000 - $132,000)", "Premium Spend (>$132,000)"))))) -> Lower-Middle Spend ($23,000 - $44,000) | F28: Lower-Middle Spend ($23,000 - $44,000) | G28: 5512 | H28: 32.961959 | I28: 121
A29: 20.73 | B29: 68 | C29: =IF(A29<22, "Low Spend (<$22,000)", IF(A29<=44, "Lower-Middle Spend ($23,000 - $44,000)", IF(A29<=66, "Middle Spend ($45,000 - $66,000)", IF(A29<=88, "Upper-Middle Spend ($67,000 - $88,000)", IF(A29<=132, "High Spend ($89,000 - $132,000)", "Premium Spend (>$132,000)"))))) -> Low Spend (<$22,000) | F29: Middle Spend ($45,000 - $66,000) | G29: 6680 | H29: 54.276685 | I29: 124
A30: 42.258 | B30: 68 | C30: =IF(A30<22, "Low Spend (<$22,000)", IF(A30<=44, "Lower-Middle Spend ($23,000 - $44,000)", IF(A30<=66, "Middle Spend ($45,000 - $66,000)", IF(A30<=88, "Upper-Middle Spend ($67,000 - $88,000)", IF(A30<=132, "High Spend ($89,000 - $132,000)", "Premium Spend (>$132,000)"))))) -> Lower-Middle Spend ($23,000 - $44,000) | F30: Premium Spend (>$132,000) | G30: 149 | H30: 135.9935 | I30: 2
A31: 66.81 | B31: 32 | C31: =IF(A31<22, "Low Spend (<$22,000)", IF(A31<=44, "Lower-Middle Spend ($23,000 - $44,000)", IF(A31<=66, "Middle Spend ($45,000 - $66,000)", IF(A31<=88, "Upper-Middle Spend ($67,000 - $88,000)", IF(A31<=132, "High Spend ($89,000 - $132,000)", "Premium Spend (>$132,000)"))))) -> Upper-Middle Spend ($67,000 - $88,000) | F31: Upper-Middle Spend ($67,000 - $88,000) | G31: 5099 | H31: 75.008082 | I31: 85
A32: 8.32 | B32: 51 | C32: =IF(A32<22, "Low Spend (<$22,000)", IF(A32<=44, "Lower-Middle Spend ($23,000 - $44,000)", IF(A32<=66, "Middle Spend ($45,000 - $66,000)", IF(A32<=88, "Upper-Middle Spend ($67,000 - $88,000)", IF(A32<=132, "High Spend ($89,000 - $132,000)", "Premium Spend (>$132,000)"))))) -> Low Spend (<$22,000) | F32: Grand Total | G32: 20755 | H32: 49.252745 | I32: 400
A33: 76.06 | B33: 39 | C33: =IF(A33<22, "Low Spend (<$22,000)", IF(A33<=44, "Lower-Middle Spend ($23,000 - $44,000)", IF(A33<=66, "Middle Spend ($45,000 - $66,000)", IF(A33<=88, "Upper-Middle Spend ($67,000 - $88,000)", IF(A33<=132, "High Spend ($89,000 - $132,000)", "Premium Spend (>$132,000)"))))) -> Upper-Middle Spend ($67,000 - $88,000)
A34: 69.683 | B34: 48 | C34: =IF(A34<22, "Low Spend (<$22,000)", IF(A34<=44, "Lower-Middle Spend ($23,000 - $44,000)", IF(A34<=66, "Middle Spend ($45,000 - $66,000)", IF(A34<=88, "Upper-Middle Spend ($67,000 - $88,000)", IF(A34<=132, "High Spend ($89,000 - $132,000)", "Premium Spend (>$132,000)"))))) -> Upper-Middle Spend ($67,000 - $88,000)
A35: 12.763 | B35: 12 | C35: =IF(A35<22, "Low Spend (<$22,000)", IF(A35<=44, "Lower-Middle Spend ($23,000 - $44,000)", IF(A35<=66, "Middle Spend ($45,000 - $66,000)", IF(A35<=88, "Upper-Middle Spend ($67,000 - $88,000)", IF(A35<=132, "High Spend ($89,000 - $132,000)", "Premium Spend (>$132,000)"))))) -> Low Spend (<$22,000)
A36: 71.554 | B36: 101 | C36: =IF(A36<22, "Low Spend (<$22,000)", IF(A36<=44, "Lower-Middle Spend ($23,000 - $44,000)", IF(A36<=66, "Middle Spend ($45,000 - $66,000)", IF(A36<=88, "Upper-Middle Spend ($67,000 - $88,000)", IF(A36<=132, "High Spend ($89,000 - $132,000)", "Premium Spend (>$132,000)"))))) -> Upper-Middle Spend ($67,000 - $88,000)
A37: 25.687 | B37: 18 | C37: =IF(A37<22, "Low Spend (<$22,000)", IF(A37<=44, "Lower-Middle Spend ($23,000 - $44,000)", IF(A37<=66, "Middle Spend ($45,000 - $66,000)", IF(A37<=88, "Upper-Middle Spend ($67,000 - $88,000)", IF(A37<=132, "High Spend ($89,000 - $132,000)", "Premium Spend (>$132,000)"))))) -> Lower-Middle Spend ($23,000 - $44,000) | G37: Correlation and Covariance Between Total Spend and Number of Transactions
A38: 79.508 | B38: 12 | C38: =IF(A38<22, "Low Spend (<$22,000)", IF(A38<=44, "Lower-Middle Spend ($23,000 - $44,000)", IF(A38<=66, "Middle Spend ($45,000 - $66,000)", IF(A38<=88, "Upper-Middle Spend ($67,000 - $88,000)", IF(A38<=132, "High Spend ($89,000 - $132,000)", "Premium Spend (>$132,000)"))))) -> Upper-Middle Spend ($67,000 - $88,000) | G38: Measured | H38: Result
A39: 55.864 | B39: 36 | C39: =IF(A39<22, "Low Spend (<$22,000)", IF(A39<=44, "Lower-Middle Spend ($23,000 - $44,000)", IF(A39<=66, "Middle Spend ($45,000 - $66,000)", IF(A39<=88, "Upper-Middle Spend ($67,000 - $88,000)", IF(A39<=132, "High Spend ($89,000 - $132,000)", "Premium Spend (>$132,000)"))))) -> Middle Spend ($45,000 - $66,000) | G39: Relationship Strength (Correlation) | H39: =CORREL('Customer Data Set'!I:I,'Customer Data Set'!H:H) -> 0.28898746
A40: 21.869 | B40: 51 | C40: =IF(A40<22, "Low Spend (<$22,000)", IF(A40<=44, "Lower-Middle Spend ($23,000 - $44,000)", IF(A40<=66, "Middle Spend ($45,000 - $66,000)", IF(A40<=88, "Upper-Middle Spend ($67,000 - $88,000)", IF(A40<=132, "High Spend ($89,000 - $132,000)", "Premium Spend (>$132,000)"))))) -> Low Spend (<$22,000) | G40: Change Together Amount(Covariance) | H40: =_xlfn.COVARIANCE.S('Customer Data Set'!I:I,'Customer Data Set'!H:H) -> 200.05057
...

Sheet Q2(b)
A1: Gender | B1: Loyalty | C1: Customer Distribution by Gender and Loyalty Program Membership
A2: Female | B2: Yes
A3: Female | B3: Yes
A4: Female | B4: Yes
A5: Male | B5: Yes
A6: Other | B6: No
A7: Female | B7: Yes | D7: CONTINGENCY-TABLE
A8: Female | B8: No | D8: How Gender Relates to Loyalty Program Membership
A9: Male | B9: No | D9: Number of Customers by Loyalty Status | E9: Membership Status
A10: Male | B10: No | D10: Customer-Gender | E10: Not in Loyalty Program | F10: In Loyalty Program | G10: Total Customers
A11: Male | B11: Yes | D11: Female | E11: 91 | F11: 99 | G11: 190
A12: Male | B12: No | D12: Male | E12: 69 | F12: 127 | G12: 196
A13: Male | B13: Yes | D13: Other | E13: 5 | F13: 9 | G13: 14
A14: Female | B14: Yes | D14: Total Customers | E14: 165 | F14: 235 | G14: 400
A15: Male | B15: No
A16: Female | B16: No
A17: Male | B17: No
A18: Male | B18: Yes | D18: Probability-Analysis
A19: Female | B19: Yes | D19: Customer Loyalty Program and Gender Distribution
A20: Female | B20: Yes | D20: Joint Probability Table
A21: Female | B21: Yes | D21: Customer-Gender | E21: Not in Loyalty Program | F21: In Loyalty Program | G21: Total Customers
A22: Male | B22: Yes | D22: Female | E22: =91/400 -> 0.2275 | F22: =99/GETPIVOTDATA("Loyalty",$D$9) -> 0.2475 | G22: =190/GETPIVOTDATA("Loyalty",$D$9) -> 0.475
A23: Male | B23: Yes | D23: Male | E23: =69/400 -> 0.1725 | F23: =127/GETPIVOTDATA("Loyalty",$D$9) -> 0.3175 | G23: =196/GETPIVOTDATA("Loyalty",$D$9) -> 0.49
A24: Male | B24: No | D24: Other | E24: =5/GETPIVOTDATA("Loyalty",$D$9) -> 0.0125 | F24: =9/GETPIVOTDATA("Loyalty",$D$9) -> 0.0225 | G24: =14/GETPIVOTDATA("Loyalty",$D$9) -> 0.035
A25: Female | B25: No | D25: Total Customers | E25: =165/GETPIVOTDATA("Loyalty",$D$9) -> 0.4125 | F25: =235/GETPIVOTDATA("Loyalty",$D$9) -> 0.5875 | G25: =400/GETPIVOTDATA("Loyalty",$D$9) -> 1
A26: Male | B26: Yes
A27: Female | B27: No | D27: Conditional Probability
A28: Male | B28: No | D28: Gender-Based Conditional Probability for Loyalty Program Membership
A29: Female | B29: No | D29: Customer Gender | E29: Chances of NOT IN Loyalty Program (given Gender) | F29: Chances of IN Loyalty Program (given Gender) | G29: Total Percentage
A30: Male | B30: No | D30: Female | E30: =91/GETPIVOTDATA("Loyalty",$D$9,"Gender","Female") -> 0.47894737 | F30: =99/GETPIVOTDATA("Loyalty",$D$9,"Gender","Female") -> 0.52105263 | G30: =E30+F30 -> 1
A31: Female | B31: No | D31: Male | E31: =69/GETPIVOTDATA("Loyalty",$D$9,"Gender","Male") -> 0.35204082 | F31: =127/GETPIVOTDATA("Loyalty",$D$9,"Gender","Male") -> 0.64795918 | G31: =E31+F31 -> 1
A32: Male | B32: No | D32: Other | E32: =5/GETPIVOTDATA("Loyalty",$D$9,"Gender","Other") -> 0.35714286 | F32: =9/GETPIVOTDATA("Loyalty",$D$9,"Gender","Other") -> 0.64285714 | G32: =E32+F32 -> 1
A33: Female | B33: Yes
A34: Female | B34: Yes
A35: Female | B35: Yes
A36: Female | B36: Yes
A37: Female | B37: Yes
A38: Male | B38: No
A39: Female | B39: Yes
A40: Male | B40: No
...

Sheet Q2(c)
A1: Age | B1: Disc_Usage | C1: Age_Groups | F1: Analysis of Age Group and Discount Usage
A2: 67 | B2: Frequently | C2: =IF(A2<30,"18-29",IF(A2<45,"30-44",IF(A2<60,"45-59","60+"))) -> 60+
A3: 20 | B3: Occasionally | C3: =IF(A3<30,"18-29",IF(A3<45,"30-44",IF(A3<60,"45-59","60+"))) -> 18-29
A4: 43 | B4: Occasionally | C4: =IF(A4<30,"18-29",IF(A4<45,"30-44",IF(A4<60,"45-59","60+"))) -> 30-44
A5: 51 | B5: Occasionally | C5: =IF(A5<30,"18-29",IF(A5<45,"30-44",IF(A5<60,"45-59","60+"))) -> 45-59 | D5: The AgeGroup Column sorts customers age by how much they use discounts, making it easier to understand their buying habits and create better strategies for different customer type | H5: Age Group
A6: 57 | B6: Occasionally | C6: =IF(A6<30,"18-29",IF(A6<45,"30-44",IF(A6<60,"45-59","60+"))) -> 45-59 | H6: Descriptive Statistics
A7: 40 | B7: Occasionally | C7: =IF(A7<30,"18-29",IF(A7<45,"30-44",IF(A7<60,"45-59","60+"))) -> 30-44 | H7: Statistic | I7: Value
A8: 74 | B8: Occasionally | C8: =IF(A8<30,"18-29",IF(A8<45,"30-44",IF(A8<60,"45-59","60+"))) -> 60+ | H8: Average Age | I8: =AVERAGE(A2:A401) -> 46.55
A9: 41 | B9: Occasionally | C9: =IF(A9<30,"18-29",IF(A9<45,"30-44",IF(A9<60,"45-59","60+"))) -> 30-44 | H9: Most Common Age | I9: =MODE(A2:A401) -> 58
A10: 69 | B10: Occasionally | C10: =IF(A10<30,"18-29",IF(A10<45,"30-44",IF(A10<60,"45-59","60+"))) -> 60+ | H10: Age Range | I10: =MAX(A2:A401)-MIN(A2:A401) -> 57
A11: 53 | B11: Occasionally | C11: =IF(A11<30,"18-29",IF(A11<45,"30-44",IF(A11<60,"45-59","60+"))) -> 45-59
A12: 51 | B12: Occasionally | C12: =IF(A12<30,"18-29",IF(A12<45,"30-44",IF(A12<60,"45-59","60+"))) -> 45-59
A13: 42 | B13: Frequently | C13: =IF(A13<30,"18-29",IF(A13<45,"30-44",IF(A13<60,"45-59","60+"))) -> 30-44 | H13: Disk_Usage
A14: 40 | B14: Occasionally | C14: =IF(A14<30,"18-29",IF(A14<45,"30-44",IF(A14<60,"45-59","60+"))) -> 30-44 | H14: Descriptive Statistics
A15: 54 | B15: Never | C15: =IF(A15<30,"18-29",IF(A15<45,"30-44",IF(A15<60,"45-59","60+"))) -> 45-59 | H15: Frequency of Discount Usage | I15: Count of Each Discount Usage Category
A16: 58 | B16: Never | C16: =IF(A16<30,"18-29",IF(A16<45,"30-44",IF(A16<60,"45-59","60+"))) -> 45-59 | H16: Frequently | I16: 129
A17: 64 | B17: Occasionally | C17: =IF(A17<30,"18-29",IF(A17<45,"30-44",IF(A17<60,"45-59","60+"))) -> 60+ | H17: Never | I17: 69
A18: 48 | B18: Never | C18: =IF(A18<30,"18-29",IF(A18<45,"30-44",IF(A18<60,"45-59","60+"))) -> 45-59 | H18: Occasionally | I18: 202
A19: 48 | B19: Frequently | C19: =IF(A19<30,"18-29",IF(A19<45,"30-44",IF(A19<60,"45-59","60+"))) -> 45-59 | H19: Grand Total | I19: 400
A20: 49 | B20: Occasionally | C20: =IF(A20<30,"18-29",IF(A20<45,"30-44",IF(A20<60,"45-59","60+"))) -> 45-59
A21: 25 | B21: Occasionally | C21: =IF(A21<30,"18-29",IF(A21<45,"30-44",IF(A21<60,"45-59","60+"))) -> 18-29 | H21: Summary Measure
A22: 65 | B22: Frequently | C22: =IF(A22<30,"18-29",IF(A22<45,"30-44",IF(A22<60,"45-59","60+"))) -> 60+ | H22: Parameter | I22: Age | J22: Disc_Usage
A23: 42 | B23: Frequently | C23: =IF(A23<30,"18-29",IF(A23<45,"30-44",IF(A23<60,"45-59","60+"))) -> 30-44 | H23: Mode | I23: 45–59 | J23: Occasionally
A24: 18 | B24: Occasionally | C24: =IF(A24<30,"18-29",IF(A24<45,"30-44",IF(A24<60,"45-59","60+"))) -> 18-29
A25: 65 | B25: Frequently | C25: =IF(A25<30,"18-29",IF(A25<45,"30-44",IF(A25<60,"45-59","60+"))) -> 60+
A26: 38 | B26: Frequently | C26: =IF(A26<30,"18-29",IF(A26<45,"30-44",IF(A26<60,"45-59","60+"))) -> 30-44 | H26: Contingency Table: Relationship Between Age Group and Discount Usage
A27: 51 | B27: Occasionally | C27: =IF(A27<30,"18-29",IF(A27<45,"30-44",IF(A27<60,"45-59","60+"))) -> 45-59
A28: 20 | B28: Occasionally | C28: =IF(A28<30,"18-29",IF(A28<45,"30-44",IF(A28<60,"45-59","60+"))) -> 18-29 | H28: Age_Groups of customers | I28: Disc_Usage
A29: 30 | B29: Never | C29: =IF(A29<30,"18-29",IF(A29<45,"30-44",IF(A29<60,"45-59","60+"))) -> 30-44 | H29: AGE_Groups | I29: Frequently | J29: Never | K29: Occasionally | L29: Grand Total
A30: 37 | B30: Never | C30: =IF(A30<30,"18-29",IF(A30<45,"30-44",IF(A30<60,"45-59","60+"))) -> 30-44 | H30: 18-29 | I30: 31 | J30: 14 | K30: 46 | L30: 91
A31: 74 | B31: Never | C31: =IF(A31<30,"18-29",IF(A31<45,"30-44",IF(A31<60,"45-59","60+"))) -> 60+ | H31: 30-44 | I31: 30 | J31: 16 | K31: 38 | L31: 84
A32: 70 | B32: Frequently | C32: =IF(A32<30,"18-29",IF(A32<45,"30-44",IF(A32<60,"45-59","60+"))) -> 60+ | H32: 45-59 | I32: 35 | J32: 23 | K32: 60 | L32: 118
A33: 19 | B33: Occasionally | C33: =IF(A33<30,"18-29",IF(A33<45,"30-44",IF(A33<60,"45-59","60+"))) -> 18-29 | H33: 60+ | I33: 33 | J33: 16 | K33: 58 | L33: 107
A34: 75 | B34: Occasionally | C34: =IF(A34<30,"18-29",IF(A34<45,"30-44",IF(A34<60,"45-59","60+"))) -> 60+ | H34: Grand Total | I34: 129 | J34: 69 | K34: 202 | L34: 400
A35: 66 | B35: Never | C35: =IF(A35<30,"18-29",IF(A35<45,"30-44",IF(A35<60,"45-59","60+"))) -> 60+
A36: 36 | B36: Occasionally | C36: =IF(A36<30,"18-29",IF(A36<45,"30-44",IF(A36<60,"45-59","60+"))) -> 30-44 | H36: Relationship Between Age Group and Discount Usag
A37: 72 | B37: Never | C37: =IF(A37<30,"18-29",IF(A37<45,"30-44",IF(A37<60,"45-59","60+"))) -> 60+ | H37: Age Group | I37: Never (%) | J37: Occasionally(%) | K37: Frequently (%) | L37: Total (%)
A38: 27 | B38: Occasionally | C38: =IF(A38<30,"18-29",IF(A38<45,"30-44",IF(A38<60,"45-59","60+"))) -> 18-29 | H38: Under 30 | I38: =COUNTIFS($C$2:$C$401, "18-29", $B$2:$B$401, "Never") / 400 -> 0.035 | J38: =COUNTIFS($C$2:$C$401, "18-29", $B$2:$B$401, "Occasionally") / 400 -> 0.115 | K38: =COUNTIFS($C$2:$C$401, "18-29", $B$2:$B$401, "Frequently") / 400 -> 0.0775 | L38: =SUM(I38:K38) -> 0.2275
A39: 18 | B39: Never | C39: =IF(A39<30,"18-29",IF(A39<45,"30-44",IF(A39<60,"45-59","60+"))) -> 18-29 | H39: 30–44 | I39: =COUNTIFS($C$2:$C$401, "30-44", $B$2:$B$401, "Never") / 400 -> 0.04 | J39: =COUNTIFS($C$2:$C$401, "30-44", $B$2:$B$401, "Occasionally") / 400 -> 0.095 | K39: =COUNTIFS($C$2:$C$401, "30-44", $B$2:$B$401, "Frequently") / 400 -> 0.075 | L39: =SUM(I39:K39) -> 0.21
A40: 49 | B40: Occasionally | C40: =IF(A40<30,"18-29",IF(A40<45,"30-44",IF(A40<60,"45-59","60+"))) -> 45-59 | H40: 45–59 | I40: =COUNTIFS($C$2:$C$401, "45-59", $B$2:$B$401, "Never") / 400 -> 0.0575 | J40: =COUNTIFS($C$2:$C$401, "45-59", $B$2:$B$401, "Occasionally") / 400 -> 0.15 | K40: =COUNTIFS($C$2:$C$401, "45-59", $B$2:$B$401, "Frequently") / 400 -> 0.0875 | L40: =SUM(I40:K40) -> 0.295
...

Sheet Q3(a)
A1: Return_Rate | C1: Estimating the Return Rate of Customers
A2: 0.57
A3: 0.84
A4: 12.19
A5: 31.92
A6: 44.82 | C6: Descriptive Summary
A7: 13.65 | C7: Return_Rate | F7: Numerical Data
A8: 29.2 | C8: Measure | D8: Value
A9: 37.35 | C9: Mean | D9: 24.09005 | F9: s Unknown
A10: 49.22 | C10: Standard Error | D10: 0.70983124
A11: 4.31 | C11: Median | D11: 23.81 | F11: Confidence Interval for mean (m)
A12: 14.84 | C12: Mode | D12: 24.29
A13: 20.05 | C13: Standard Deviation | D13: 14.196625 | F13: Data
A14: 43.95 | C14: Sample Variance | D14: 201.54416 | F14: Sample Standard Deviation (s) | G14: =_xlfn.STDEV.S('Customer Data Set'!P2:P401) -> 14.196625
A15: 8.36 | C15: Kurtosis | D15: -1.1807668 | F15: Sample Mean ( ) | G15: =AVERAGE('Customer Data Set'!P2:P401) -> 24.09005
A16: 0.36 | C16: Skewness | D16: 0.074560304 | F16: Sample Size (n) | G16: =COUNT('Customer Data Set'!P2:P401) -> 400
A17: 7.55 | C17: Range | D17: 49.78 | F17: Confidence Level | G17: 0.95
A18: 16.65 | C18: Minimum | D18: 0.2
A19: 45.26 | C19: Maximum | D19: 49.98 | F19: Intermediate Calculations
A20: 47.76 | C20: Sum | D20: 9636.02 | F20: Standard Error of the Mean ( ) | G20: =G14/SQRT(G16) -> 0.70983124
A21: 2.65 | C21: Count | D21: 400 | F21: Degrees of Freedom (df = n-1) | G21: =G16-1 -> 399
A22: 24.29 | F22: t Value | G22: =_xlfn.T.INV.2T(1-G17,G21) -> 1.9659273
A23: 32.71 | F23: Sampling Error/Margin of Error (= SE * t Value) | G23: =G20*G22 -> 1.3954766
A24: 5.56 | C24: Quartile and Percentile Summary
A25: 8.52 | C25: Measure | D25: Value | F25: Confidence Interval
A26: 33.01 | C26: Q1 (25th percentile) | D26: =_xlfn.QUARTILE.EXC(A2:A401,1) -> 12.1375 | F26: Interval Lower Limit (= Sample Mean - ME) | G26: =G15-G23 -> 22.694573
A27: 45.35 | C27: Q3 (75th percentile) | D27: =_xlfn.QUARTILE.EXC(A2:A401,3) -> 36.1925 | F27: Interval Upper Limit (= Sample Mean + ME) | G27: =G15+G23 -> 25.485527
A28: 6.9 | C28: Inter-Quartile-Range | D28: =D27-D26 -> 24.055
A29: 29.77
A30: 39.27
A31: 33.85
A32: 40.82
A33: 13.06
A34: 5.43
A35: 16.61
A36: 9.41
A37: 14.58
A38: 12
A39: 10.08
A40: 46.47
...

Sheet Q3(b)
A1: Online_Freq | C1: Estimate the Proportion Of customers Who Shop Often or Always
A2: Rarely
A3: Rarely
A4: Sometimes
A5: Often
A6: Sometimes | C6: Online-purchase Frequency-Distribution
A7: Often | C7: Online Purchase Frequency | D7: Customer Count | E7: Percentage of Total
A8: Rarely | C8: Always | D8: 38 | E8: 0.094763092
A9: Often | C9: Often | D9: 110 | E9: 0.27431421
A10: Often | C10: Rarely | D10: 88 | E10: 0.21945137
A11: Sometimes | C11: Sometimes | D11: 164 | E11: 0.40897756
A12: Rarely | C12: Total | D12: 400 | E12: 1
A13: Often
A14: Rarely
A15: Sometimes | D15: Descriptive-Statistics
A16: Rarely | D16: Statistical Summary | E16: Value
A17: Often | D17: Mode | E17: Sometimes
A18: Sometimes | D18: Frequency (Count) | E18: 164 Customers
A19: Always | D19: % of Total | E19: 0.409
A20: Always | D20: Total Responses | E20: 400 Customers
A21: Rarely
A22: Rarely
A23: Rarely
A24: Sometimes | C24: Customer Shopping "Always" and "Often"
A25: Often | C25: Customer Shopping Habits | D25: Count of Customers | E25: Proportion of Customers
A26: Rarely | C26: Always | D26: 38 | E26: =D26/400 -> 0.095
A27: Often | C27: Often | D27: 110 | E27: =110/400 -> 0.275
A28: Sometimes
A29: Often
A30: Always
A31: Rarely
A32: Sometimes | C32: Categorical Data
A33: Sometimes
A34: Rarely | C34: Confidence Interval for proportion
A35: Rarely
A36: Sometimes | C36: Data
A37: Often | C37: Sample Size (n) | D37: =COUNTA(A2:A401) -> 400
A38: Often | C38: Count of Successes | D38: =D9 -> 110
A39: Often | C39: Confidence Level | D39: 0.95
A40: Sometimes
...

Sheet Q4(a)
A1: Total_Spend | B1: Spending_Groups | D1: Assessing Customer Spending in Relation to Market Expectations
A2: 17.388 | B2: Low Spend (<$22,000)
A3: 46.657 | B3: Middle Spend ($45,000 - $66,000) | D3: Confidence Interval for mean (m)
A4: 68.616 | B4: Upper-Middle Spend ($67,000 - $88,000)
A5: 28.392 | B5: Lower-Middle Spend ($23,000 - $44,000) | D5: Data
A6: 43.87 | B6: Lower-Middle Spend ($23,000 - $44,000) | D6: Sample Standard Deviation (s) | E6: 23.607615
A7: 65.685 | B7: Middle Spend ($45,000 - $66,000) | D7: Sample Mean ( ) | E7: 49.252745
A8: 25.865 | B8: Lower-Middle Spend ($23,000 - $44,000) | D8: Sample Size (n) | E8: 400
A9: 40.754 | B9: Lower-Middle Spend ($23,000 - $44,000) | D9: Confidence Level | E9: 0.95
A10: 16.122 | B10: Low Spend (<$22,000)
A11: 43.776 | B11: Lower-Middle Spend ($23,000 - $44,000) | D11: Intermediate Calculations
A12: 63.608 | B12: Middle Spend ($45,000 - $66,000) | D12: Standard Error of the Mean ( ) | E12: =E6/SQRT(E8) -> 1.1803808
A13: 35.884 | B13: Lower-Middle Spend ($23,000 - $44,000) | D13: Degrees of Freedom (df = n-1) | E13: =E8-1 -> 399
A14: 59.943 | B14: Middle Spend ($45,000 - $66,000) | D14: t Value | E14: =_xlfn.T.INV.2T(1-0.95,E13) -> 1.9659273
A15: 55.834 | B15: Middle Spend ($45,000 - $66,000) | D15: Sampling Error/Margin of Error (= SE * t Value) | E15: =E14*E12 -> 2.3205427
A16: 15.707 | B16: Low Spend (<$22,000)
A17: 67.504 | B17: Upper-Middle Spend ($67,000 - $88,000) | D17: Confidence Interval
A18: 42.305 | B18: Lower-Middle Spend ($23,000 - $44,000) | D18: Interval Lower Limit (= Sample Mean - ME) | E18: =49.25-2.32 -> 46.93
A19: 45.494 | B19: Middle Spend ($45,000 - $66,000) | D19: Interval Upper Limit (= Sample Mean + ME) | E19: =49.25+2.32 -> 51.57
A20: 25.003 | B20: Lower-Middle Spend ($23,000 - $44,000)
A21: 46.646 | B21: Middle Spend ($45,000 - $66,000)
A22: 32.248 | B22: Lower-Middle Spend ($23,000 - $44,000)
A23: 71.543 | B23: Upper-Middle Spend ($67,000 - $88,000)
A24: 37.269 | B24: Lower-Middle Spend ($23,000 - $44,000)
A25: 34.419 | B25: Lower-Middle Spend ($23,000 - $44,000) | D25: s Unknown
A26: 62.975 | B26: Middle Spend ($45,000 - $66,000) | D26: Hypothesis Test for µ
A27: 51.877 | B27: Middle Spend ($45,000 - $66,000)
A28: 38.255 | B28: Lower-Middle Spend ($23,000 - $44,000) | D28: Hypotheses
A29: 20.73 | B29: Low Spend (<$22,000) | D29: Null Hypothesis | E29: µ | G29: 48
A30: 42.258 | B30: Lower-Middle Spend ($23,000 - $44,000) | D30: Alternative Hypothesis | E30: µ | F30: > | G30: 48
A31: 66.81 | B31: Upper-Middle Spend ($67,000 - $88,000) | D31: Test Type | F31: One-Tailed | G31: =IF(F30="<","Lower",IF(F30=">","Upper","Two")) -> Upper
A32: 8.32 | B32: Low Spend (<$22,000) | D32: Level of significance
A33: 76.06 | B33: Upper-Middle Spend ($67,000 - $88,000) | G33: 0.05
A34: 69.683 | B34: Upper-Middle Spend ($67,000 - $88,000) | D34: Critical Region
A35: 12.763 | B35: Low Spend (<$22,000) | D35: Degrees of Freedom | G35: =E8-1 -> 399
A36: 71.554 | B36: Upper-Middle Spend ($67,000 - $88,000) | D36: =IF(F29="=","Lower Critical Value","Critical Value") -> Critical Value | G36: =_xlfn.T.INV(1-G33,G35) -> 1.6486815
A37: 25.687 | B37: Lower-Middle Spend ($23,000 - $44,000) | D37: =IF(F29="=","Upper Critical Value","")
A38: 79.508 | B38: Upper-Middle Spend ($67,000 - $88,000) | D38: Sample Data
A39: 55.864 | B39: Middle Spend ($45,000 - $66,000) | D39: Sample Standard Deviation | G39: =E6 -> 23.607615
A40: 21.869 | B40: Low Spend (<$22,000) | D40: Sample Mean | G40: =E7 -> 49.252745
...

Sheet Q4(b)
A1: Disc_Usage | C1: Discount Usage Comparison For less than 30% of customers Frequently use discount
A2: Frequently
A3: Occasionally
A4: Occasionally
A5: Occasionally | C5: Categorical Data
A6: Occasionally
A7: Occasionally | C7: Confidence Interval for proportion
A8: Occasionally
A9: Occasionally | C9: Data
A10: Occasionally | C10: Sample Size (n) | D10: =COUNTA(A2:A401) -> 400
A11: Occasionally | C11: Count of Successes | D11: 129
A12: Occasionally | C12: Confidence Level | D12: 0.95
A13: Frequently
A14: Occasionally
A15: Never | C15: Intermediate Calculations
A16: Never | C16: Sample Proportion (p) | D16: =D11/D10 -> 0.3225
A17: Occasionally | C17: Z Value | D17: =_xlfn.NORM.S.INV(1-(1-0.95)/2) -> 1.959964
A18: Never | C18: Standard Error of the Proportion ( ) | D18: =SQRT(D16*(1-D16)/D10) -> 0.023371658
A19: Frequently | C19: Sampling Error/Margin of Error (= SE * Z Value) | D19: =D18*D17 -> 0.045807607
A20: Occasionally
A21: Occasionally | C21: Confidence Interval
A22: Frequently | C22: Interval Lower Limit (= Sample Proportion - ME) | D22: =D16-D19 -> 0.27669239
A23: Frequently | C23: Interval Upper Limit (= Sample Proportion + ME) | D23: =D16+D19 -> 0.36830761
A24: Occasionally
A25: Frequently
A26: Frequently
A27: Occasionally | C27: Categorical data
A28: Occasionally | C28: Hypothesis Test for π
A29: Never
A30: Never | C30: Hypotheses
A31: Never | C31: Null Hypothesis | D31: π | F31: 0.3
A32: Frequently | C32: Alternative Hypothesis | D32: π | E32: < | F32: 0.3
A33: Occasionally | C33: Test Type | F33: =IF(E32="<","Lower",IF(E32=">","Upper","Two")) -> Lower
A34: Occasionally | C34: Level of significance
A35: Never | E35: α | F35: 0.05
A36: Occasionally | C36: Critical Region
A37: Never | C37: =IF(E31="=","Lower Critical Value","Critical Value") -> Critical Value | F37: =_xlfn.NORM.S.INV(0.05) -> -1.6448536
A38: Occasionally | C38: =IF(E31="=","Upper Critical Value","")
A39: Never | C39: Sample Data
A40: Occasionally | C40: Sample Size | F40: =COUNTA(A2:A401) -> 400
...

Sheet Q5
A1: Total_Spend | B1: Online_Freq | F1: Calculating the Required Sample Size for Online Shopping Frequency
A2: 17.388 | B2: Rarely
A3: 46.657 | B3: Rarely
A4: 68.616 | B4: Sometimes
A5: 28.392 | B5: Often | F5: Numerical Data | I5: Numerical Data
A6: 43.87 | B6: Sometimes
A7: 65.685 | B7: Often | F7: Sample size for a Mean | I7: Sample size for a Mean
A8: 25.865 | B8: Rarely
A9: 40.754 | B9: Often | F9: Data | I9: Data
A10: 16.122 | B10: Often | F10: Population OR Sample Standard Deviation ( s or s) | G10: =_xlfn.STDEV.S(A2:A401) -> 23.607615 | I10: Population OR Sample Standard Deviation ( s or s) | J10: =_xlfn.STDEV.S(A2:A401) -> 23.607615
A11: 43.776 | B11: Sometimes | F11: Sampling Error/Margin of Error | G11: 2000 | I11: Sampling Error/Margin of Error | J11: 2000
A12: 63.608 | B12: Rarely | F12: Confidence Level | G12: 0.95 | I12: Confidence Level | J12: 0.9
A13: 35.884 | B13: Often
A14: 59.943 | B14: Rarely | F14: Intermediate Calculations | I14: Intermediate Calculations
A15: 55.834 | B15: Sometimes | F15: Z value | G15: 1.96 | I15: Z value | J15: =_xlfn.NORM.S.INV((1-0.1/2)) -> 1.6448536
A16: 15.707 | B16: Rarely | F16: Calculated Sample Size | G16: =(G15*G10/2)^2 -> 535.24964 | I16: Calculated Sample Size | J16: =(J15*J10/2)^2 -> 376.96303
A17: 67.504 | B17: Often
A18: 42.305 | B18: Sometimes | F18: Result | I18: Result
A19: 45.494 | B19: Always | F19: Minimum Sample Size Needed | G19: 536 | I19: Minimum Sample Size Needed | J19: =_xlfn.CEILING.MATH(J16) -> 377
A20: 25.003 | B20: Always
A21: 46.646 | B21: Rarely
A22: 32.248 | B22: Rarely
A23: 71.543 | B23: Rarely
A24: 37.269 | B24: Sometimes | G24: Numerical Data
A25: 34.419 | B25: Often
A26: 62.975 | B26: Rarely | G26: Sample size for a Mean
A27: 51.877 | B27: Often
A28: 38.255 | B28: Sometimes | G28: Data
A29: 20.73 | B29: Often | G29: Population OR Sample Standard Deviation ( s or s) | H29: =_xlfn.STDEV.S(A2:A401) -> 23.607615
A30: 42.258 | B30: Always | G30: Sampling Error/Margin of Error | H30: 2000
A31: 66.81 | B31: Rarely | G31: Confidence Level | H31: 0.99
A32: 8.32 | B32: Sometimes
A33: 76.06 | B33: Sometimes | G33: Intermediate Calculations
A34: 69.683 | B34: Rarely | G34: Z value | H34: =_xlfn.NORM.S.INV(1-0.01/2) -> 2.5758293
A35: 12.763 | B35: Rarely | G35: Calculated Sample Size | H35: =(H34*H29/2)^2 -> 924.4393
A36: 71.554 | B36: Sometimes
A37: 25.687 | B37: Often | G37: Result
A38: 79.508 | B38: Often | G38: Minimum Sample Size Needed | H38: 925
A39: 55.864 | B39: Often
A40: 21.869 | B40: Sometimes
...

Sheet CI
B2: Numerical Data | F2: Numerical Data
B4: s Known | F4: s Unknown | J4: Categorical Data
B6: Confidence Interval for mean (m) | F6: Confidence Interval for mean (m) | J6: Confidence Interval for proportion
B8: Data | F8: Data | J8: Data
B9: Population Standard Deviation (s) | F9: Sample Standard Deviation (s) | J9: Sample Size (n)
B10: Sample Mean ( ) | F10: Sample Mean ( ) | J10: Count of Successes
B11: Sample Size (n) | F11: Sample Size (n) | J11: Confidence Level
B12: Confidence Level | F12: Confidence Level
B14: Intermediate Calculations | F14: Intermediate Calculations | J14: Intermediate Calculations
B15: Standard Error of the Mean ( ) | F15: Standard Error of the Mean ( ) | J15: Sample Proportion (p)
B16: Z Value | F16: Degrees of Freedom (df = n-1) | J16: Z Value
B17: Sampling Error/Margin of Error (= SE *Z Value) | F17: t Value | J17: Standard Error of the Proportion ( )
F18: Sampling Error/Margin of Error (= SE * t Value) | J18: Sampling Error/Margin of Error (= SE * Z Value)
B19: Confidence Interval
B20: Interval Lower Limit (= Sample Mean - ME) | F20: Confidence Interval | J20: Confidence Interval
B21: Interval Upper Limit (= Sample Mean + ME) | F21: Interval Lower Limit (= Sample Mean - ME) | J21: Interval Lower Limit (= Sample Proportion - ME)
F22: Interval Upper Limit (= Sample Mean + ME) | J22: Interval Upper Limit (= Sample Proportion + ME)

Sheet HT
B2: s Unknown | H2: s Known | N2: Categorical data
B3: Hypothesis Test for µ | H3: Hypothesis Test for µ (Mean) | N3: Hypothesis Test for π
B5: Hypotheses | H5: Hypotheses | N5: Hypotheses
B6: Null Hypothesis | C6: µ | D6: =IF(D7=">",$AC$4,IF(D7="<",$AC$5,$AC$6)) -> 0 | H6: Null Hypothesis | I6: µ | N6: Null Hypothesis | O6: π
B7: Alternative Hypothesis | C7: µ | H7: Alternative Hypothesis | I7: µ | N7: Alternative Hypothesis | O7: π
B8: Test Type | E8: =IF(D7="<","Lower",IF(D7=">","Upper","Two")) -> Two | H8: Test Type | K8: =IF(J7="<","Lower",IF(J7=">","Upper","Two")) -> Two | N8: Test Type | Q8: =IF(P7="<","Lower",IF(P7=">","Upper","Two")) -> Two
B9: Level of significance | H9: Level of significance | N9: Level of significance
D10: α | J10: α | P10: α
B11: Critical Region | H11: Critical Region | N11: Critical Region
B12: Degrees of Freedom | H12: Critical Value (s) | N12: =IF(P6="=","Lower Critical Value","Critical Value") -> Critical Value
B13: =IF(D6="=","Lower Critical Value","Critical Value") -> Critical Value | N13: =IF(P6="=","Upper Critical Value","")
B14: =IF(D6="=","Upper Critical Value","") | H14: Population Standard Deviation | N14: Sample Data
B15: Sample Data | N15: Sample Size
B16: Sample Standard Deviation | H16: Sample Data | N16: Count of 'Successes'
B17: Sample Mean | H17: Sample Mean
B18: Sample Size | H18: Sample Size | N18: Sample proportion, p
N19: Standard Error
B20: Standard Error of the Mean | H20: Standard Error of the Mean | N20: z Sample Statistic
B21: t Sample Statistic | H21: Z Sample Statistic | N21: p-value
B22: p-value | H22: p-value
N23: Decision
B24: Decision | H24: Decision | N24: =IF(Q21<Q10,"Reject Null Hypothesis", "Fail to reject Null Hypothesis") -> Fail to reject Null Hypothesis
B25: =IF(E22<E10,"Reject Null Hypothesis", "Fail to reject Null Hypothesis") -> Fail to reject Null Hypothesis | H25: =IF(K22<K10,"Reject Null Hypothesis", "Fail to reject Null Hypothesis") -> Fail to reject Null Hypothesis

Sheet SampleSize
B2: Categorical Data | G2: Numerical Data
B4: Sample size for a Proportion | G4: Sample size for a Mean
B6: Data | G6: Data
B7: Estimate of True Proportion ( p or p ) | G7: Population OR Sample Standard Deviation ( s or s)
B8: Sampling Error/Margin of Error | G8: Sampling Error/Margin of Error
B9: Confidence Level | G9: Confidence Level
B11: Intermediate Calculations | G11: Intermediate Calculations
B12: Z value | G12: Z value
B13: Calculated Sample Size | G13: Calculated Sample Size
B15: Result | G15: Result
B16: Minimum Sample Size Needed | G16: Minimum Sample Size Needed
